Workbook

Sheet SKLAD
A1: Na skladě připraveno pro výrobu
A2: Komponenty | C2: Na skladě | D2: Cena/ks | E2: Cena celkem | F2: Potřeba na 1 výr. | H2: Lze vyrobit ks
A3: Brown Switche | C3: 30 | D3: ='DASHCLUSTER classic V1'!I34 -> 5.7926667 | E3: =C3*D3 -> 173.78 | F3: 12 | H3: {=MIN(IF(F3:F33>0,INT(C3:C33/F3:F33)))} -> 1
A4: LED pásek (pro jednotlivé LED) | C4: 144 | D4: ='DASHCLUSTER classic V1'!I35 -> 0.914375 | E4: =C4*D4 -> 131.67 | F4: 12 | H4: Hodnota skladu
A5: Raspberry Pi Pico klon 16MB, USB-C | C5: 1 | D5: ='DASHCLUSTER classic V1'!I36 -> 40.22 | E5: =C5*D5 -> 40.22 | F5: 1 | H5: =SUM(E3:E33) -> 1158.3562
A6: PCB (počítat s velkovýrobní cenou) | C6: 5 | D6: ='DASHCLUSTER classic V1'!I37 -> 71.09 | E6: =C6*D6 -> 355.45 | F6: 1 | H6: Potřeba dokoupit ks
A7: Datový kabel USB-C | C7: 2 | D7: ='DASHCLUSTER classic V1'!I38 -> 28.576 | E7: =C7*D7 -> 57.152 | F7: 1 | H7: {=SUM(IF(F3:F33>C3:C33, F3:F33-C3:C33, 0))} -> 0
A8: Dupont kabely samec-samice | C8: 10 | D8: ='DASHCLUSTER classic V1'!I39 -> 0.36175 | E8: =C8*D8 -> 3.6175 | F8: 5 | H8: Na hranici
A9: Šrouby M2x10mm | C9: 0 | D9: ='DASHCLUSTER classic V1'!I40 -> 0.2706 | E9: =C9*D9 -> 0 | F9: 0 | H9: {=SUM(IF((C3:C33-F3:F33<=2)*(C3:C33-F3:F33>=0)*(F3:F33>0), 1, 0))} -> 2
A10: Matice M2 | C10: 0 | D10: ='DASHCLUSTER classic V1'!I41 -> 0.2295 | E10: =C10*D10 -> 0 | F10: 0
A11: Distanční sloupky M2, různé velikosti | C11: 0 | D11: ='DASHCLUSTER classic V1'!I42 -> 0.84175 | E11: =C11*D11 -> 0 | F11: 0
A12: Resin černý standart Anycubic (Water-Washable) | C12: 500 | D12: ='DASHCLUSTER classic V1'!I43 -> 0.40775333 | E12: =C12*D12 -> 203.87667 | F12: 250
A13: 3 pozicový spínač zapalování | C13: 0 | D13: ='DASHCLUSTER classic V1'!I44 -> 89.62 | E13: =C13*D13 -> 0 | F13: 0
A14: Expander GPIO pinů | C14: 0 | D14: ='DASHCLUSTER classic V1'!I45 -> 0 | E14: =C14*D14 -> 0 | F14: 0
A15: Uzavíratelné sáčky | C15: 0 | D15: ='DASHCLUSTER classic V1'!I46 -> 0.15131 | E15: =C15*D15 -> 0 | F15: 0
A16: Krabice 300x250x150mm | C16: 0 | D16: ='DASHCLUSTER classic V1'!I47 -> 15.955 | E16: =C16*D16 -> 0 | F16: 0
A17: Etiketa - samolepící papír do tiskárny | C17: 0 | D17: ='DASHCLUSTER classic V1'!I48 -> 1.19 | E17: =C17*D17 -> 0 | F17: 0
A18: Flashdisk 4GB - návod atd. | C18: 0 | D18: ='DASHCLUSTER classic V1'!I49 -> 34.32 | E18: =C18*D18 -> 0 | F18: 0
A19: Rezistory 330R 0.25W | C19: 20 | D19: ='DASHCLUSTER classic V1'!I50 -> 3.9765 | E19: =C19*D19 -> 79.53 | F19: 1
A20: Keramický kondenzátor | C20: 100 | D20: ='DASHCLUSTER classic V1'!I51 -> 0.4334 | E20: =C20*D20 -> 43.34 | F20: 12
A21: Elektrolytický kondenzátor | C21: 20 | D21: ='DASHCLUSTER classic V1'!I52 -> 3.486 | E21: =C21*D21 -> 69.72 | F21: 1

Sheet DASHCLUSTER classic V1
A1: Výpočet nákladů, prodejů a zisků | G1: Dnes je | H1: =TODAY() -> 46157 | J1: Zadej a změň
A2: Kolik (ks) jakých materiálů/komponent bylo potřeba? | G2: kusy/gramy | H2: cena | J2: Marže (v %) | L2: 1.7
A3: Brown Switche | G3: 12 | H3: =G3*I34 -> 69.512 | J3: Daň (v %) | L3: 0.15
A4: LED pásek (pro jednotlivé LED) | G4: 12 | H4: =G4*I35 -> 10.9725 | J4: Odečtení daní
A5: Raspberry Pi Pico klon 16MB, USB-C | G5: 1 | H5: =G5*I36 -> 40.22
A6: PCB (počítat s velkovýrobní cenou) | G6: 1 | H6: =G6*I37 -> 71.09
A7: Datový kabel USB-C | G7: 1 | H7: =G7*I38 -> 28.576
A8: Dupont kabely samec-samice | H8: =G8*I39 -> 0
A9: Šrouby M2x10mm | H9: =G9*I40 -> 0 | K9: Celkové náklady | M9: =SUM(H3:H30)*(1-L4) -> 368.55073
A10: Matice M2 | H10: =G10*I41 -> 0 | K10: Hrubý výdělek | M10: =M9*(1+L2) -> 995.08698
A11: Distanční sloupky M2, různé velikosti | H11: =G11*I42 -> 0 | K11: Výdělek bez nákladů | M11: =M13-M9 -> 630.44927
A12: Resin černý standart Anycubic (Water-Washable) | G12: 250 | H12: =G12*I43 -> 101.93833 | K12: Čistý výdělek | M12: =M11*(1-L3) -> 535.88188
A13: 3 pozicový spínač zapalování | H13: =G13*I44 -> 0 | K13: Prodejní cena | M13: =MIN(ROUNDUP((M10-49)/100,0)*100+49, ROUNDUP((M10-99)/100,0)*100+99) -> 999
A14: Expander GPIO pinů | H14: =G14*I45 -> 0
A15: Uzavíratelné sáčky | H15: =G15*I46 -> 0
A16: Krabice 300x250x150mm | H16: =G16*I47 -> 0
A17: Etiketa - samolepící papír do tiskárny | H17: =G17*I48 -> 0
A18: Flashdisk 4GB - návod atd. | H18: =G18*I49 -> 0
A19: Rezistory | G19: 1 | H19: =G19*I50 -> 3.9765
A20: Keramický kondenzátor | G20: 1 | H20: =G20*I51 -> 0.4334
A21: Elektrolytický kondenzátor | G21: 12 | H21: =G21*I52 -> 41.832
H22: =G22*I53 -> 0
H23: =G23*I54 -> 0
H24: =G24*I55 -> 0
H25: =G25*I56 -> 0
H26: =G26*I57 -> 0
H27: =G27*I58 -> 0
H28: =G28*I59 -> 0
H29: =G29*I60 -> 0
H30: =G30*I61 -> 0
A33: Materiál/komponenta nutné k výrobě jednoho kusu | G33: cena | H33: ks v balení | I33: cena 1ks | L33: Materiál/komponenta použitelné opakovaně | R33: cena 1ks | S33: potřeba dokoupit kusů | T33: celková cena
A34: Brown Switche | G34: 173.78 | H34: 30 | I34: =IF(H34=0,0,G34/H34) -> 5.7926667 | L34: Cín na pájení | R34: 29 | S34: 10 | T34: =R34*S34 -> 290
A35: LED pásek (pro jednotlivé LED) | G35: 131.67 | H35: 144 | I35: =IF(H35=0,0,G35/H35) -> 0.914375 | L35: Kalafuna | R35: 31 | S35: 2 | T35: =R35*S35 -> 62
A36: Raspberry Pi Pico klon 16MB, USB-C | G36: 40.22 | H36: 1 | I36: =IF(H36=0,0,G36/H36) -> 40.22 | L36: PCB testovacích desek (5 je minimum výrobce) | R36: 69 | S36: 5 | T36: =R36*S36 -> 345
A37: PCB (počítat s velkovýrobní cenou) | G37: 355.45 | H37: 5 | I37: =IF(H37=0,0,G37/H37) -> 71.09 | T37: =R37*S37 -> 0
A38: Datový kabel USB-C | G38: 285.76 | H38: 10 | I38: =IF(H38=0,0,G38/H38) -> 28.576 | T38: =R38*S38 -> 0
A39: Dupont kabely samec-samice | G39: 14.47 | H39: 40 | I39: =IF(H39=0,0,G39/H39) -> 0.36175 | T39: =R39*S39 -> 0
A40: Šrouby M2x10mm | G40: 27.06 | H40: 100 | I40: =IF(H40=0,0,G40/H40) -> 0.2706 | T40: =R40*S40 -> 0
A41: Matice M2 | G41: 22.95 | H41: 100 | I41: =IF(H41=0,0,G41/H41) -> 0.2295 | T41: =R41*S41 -> 0
A42: Distanční sloupky M2, různé velikosti | G42: 101.01 | H42: 120 | I42: =IF(H42=0,0,G42/H42) -> 0.84175 | T42: =R42*S42 -> 0
...

Sheet DASHCLUSTER premium V1
A1: Výpočet nákladů, prodejů a zisků | G1: Dnes je | H1: =TODAY() -> 46157 | J1: Zadej a změň
A2: Kolik (ks) jakých materiálů/komponent bylo potřeba? | G2: kusy/gramy | H2: cena | J2: Marže (v %) | L2: 0.5
A3: Brown Switche | G3: 20 | H3: =G3*I34 -> 181.63636 | J3: Daň (v %) | L3: 0.15
A4: LED pásek (pro jednotlivé LED) | G4: 20 | H4: =G4*I35 -> 45.555556
A5: Raspberry Pi Pico klon 16MB, USB-C | G5: 1 | H5: =G5*I36 -> 91
A6: PCB (počítat s velkovýrobní cenou) | G6: 1 | H6: =G6*I37 -> 23.81
A7: Datový kabel USB-C | G7: 1 | H7: =G7*I38 -> 28
A8: Dupont kabely samec-samice | G8: 20 | H8: =G8*I39 -> 17.5
A9: Šrouby M2x10mm | H9: =G9*I40 -> 0 | K9: Celkové náklady | M9: =H3+H4+H5+H6+H7+H8+H9+H10+H11+H12+H13+H14+H15+H16+H17+H18+H19+H20+H21+H22+H23+H24+H25+H26+H27+H28+H29+H30 -> 853.33692
A10: Matice M2 | H10: =G10*I41 -> 0 | K10: Hrubý výdělek | M10: =M9*(1+L2) -> 1280.0054
A11: Distanční sloupky M2, různé velikosti | H11: =G11*I42 -> 0 | K11: Výdělek bez nákladů | M11: =M13-M9 -> 445.66308
A12: Resin High-Clear Anycubic | G12: 250 | H12: =G12*I43 -> 163.75 | K12: Čistý výdělek | M12: =M11*(1-L3) -> 378.81362
A13: 3 pozicový spínač zapalování | G13: 1 | H13: =G13*I44 -> 139 | K13: Prodejní cena | M13: =MIN(ROUNDUP((M10-49)/100,0)*100+49, ROUNDUP((M10-99)/100,0)*100+99) -> 1299
A14: Expander GPIO pinů | H14: =G14*I45 -> 0
A15: Uzavíratelné sáčky | H15: =G15*I46 -> 0
A16: Krabice 300x250x150mm | G16: 1 | H16: =G16*I47 -> 7.65
A17: Etiketa - samolepící papír do tiskárny | G17: 1 | H17: =G17*I48 -> 1.19
A18: Flashdisk 4GB - návod atd. | G18: 1 | H18: =G18*I49 -> 73
A19: Rezistory | G19: 1 | H19: =G19*I50 -> 0.395
A20: Keramický kondenzátor | G20: 1 | H20: =G20*I51 -> 0.85
A21: Elektrolytický kondenzátor | G21: 20 | H21: =G21*I52 -> 80
H22: =G22*I53 -> 0
H23: =G23*I54 -> 0
H24: =G24*I55 -> 0
H25: =G25*I56 -> 0
H26: =G26*I57 -> 0
H27: =G27*I58 -> 0
H28: =G28*I59 -> 0
H29: =G29*I60 -> 0
H30: =G30*I61 -> 0
A33: Materiál/komponenta nutné k výrobě jednoho kusu | G33: cena | H33: ks v balení | I33: cena 1ks | L33: Materiál/komponenta použitelné opakovaně | R33: cena 1ks | S33: potřeba dokoupit kusů | T33: celková cena
A34: Brown Switche | G34: 999 | H34: 110 | I34: =IF(H34=0,0,G34/H34) -> 9.0818182 | L34: Cín na pájení | R34: 29 | S34: 10 | T34: =R34*S34 -> 290
A35: LED pásek (pro jednotlivé LED) | G35: 328 | H35: 144 | I35: =IF(H35=0,0,G35/H35) -> 2.2777778 | L35: Kalafuna | R35: 31 | S35: 2 | T35: =R35*S35 -> 62
A36: Raspberry Pi Pico klon 16MB, USB-C | G36: 91 | H36: 1 | I36: =IF(H36=0,0,G36/H36) -> 91 | L36: PCB testovacích desek (5 je minimum výrobce) | R36: 69 | S36: 5 | T36: =R36*S36 -> 345
A37: PCB (počítat s velkovýrobní cenou) | G37: 2381 | H37: 100 | I37: =IF(H37=0,0,G37/H37) -> 23.81 | T37: =R37*S37 -> 0
A38: Datový kabel USB-C | G38: 28 | H38: 1 | I38: =IF(H38=0,0,G38/H38) -> 28 | T38: =R38*S38 -> 0
A39: Dupont kabely samec-samice | G39: 35 | H39: 40 | I39: =IF(H39=0,0,G39/H39) -> 0.875 | T39: =R39*S39 -> 0
A40: Šrouby M2x10mm | G40: 235 | H40: 500 | I40: =IF(H40=0,0,G40/H40) -> 0.47 | T40: =R40*S40 -> 0
A41: Matice M2 | G41: 353 | H41: 1500 | I41: =IF(H41=0,0,G41/H41) -> 0.23533333 | T41: =R41*S41 -> 0
A42: Distanční sloupky M2, různé velikosti | G42: 164 | H42: 320 | I42: =IF(H42=0,0,G42/H42) -> 0.5125 | T42: =R42*S42 -> 0
...

Sheet Rok 2026
A1: Roční přehled | G1: Dnes je | H1: =TODAY() -> 46157 | J1: Přehled
A2: Duben | G2: Roční shrnutí | J2: DASHCLUSTER classic V1 | N2: DASHCLUSTER premium V1
A3: Den | B3: Jiné výdaje (Kč) | C3: Jiné příjmy (Kč) | D3: Prodeje (vyber) | E3: Prodáno kusů | F3: Výsledek za den | G3: Jiné výdaje | H3: =SUM(B4:B33)+SUM(B37:B67)+SUM(B71:B100)+SUM(B104:B134)+SUM(B138:B168)+SUM(B172:B201)+SUM(B205:B235)+SUM(B239:B268)+SUM(B272:B302) -> 0 | J3: Marže (v %) | L3: ='DASHCLUSTER classic V1'!L2 -> 1.7 | N3: Marže (v %) | P3: ='DASHCLUSTER premium V1'!L2 -> 0.5
A4: 1. dubna | D4: Bez prodejů | F4: =IF(D4="DASHCLUSTER classic V1",(E4*$L$8)-B4+C4,IF(D4="DASHCLUSTER premium V1",(E4*$P$8)-B4+C4,IF(D4="Bez prodejů",-B4+C4,""))) -> 0 | G4: Jiné příjmy | H4: =SUM(C4:C33)+SUM(C37:C67)+SUM(C71:C100)+SUM(C104:C134)+SUM(C138:C168)+SUM(C172:C201)+SUM(C205:C235)+SUM(C239:C268)+SUM(C272:C302) -> 0 | J4: Daň (v %) | L4: ='DASHCLUSTER classic V1'!L3 -> 0.15 | N4: Daň (v %) | P4: ='DASHCLUSTER premium V1'!L3 -> 0.15
A5: 2. dubna | D5: Bez prodejů | F5: =IF(D5="DASHCLUSTER classic V1",(E5*$L$8)-B5+C5,IF(D5="DASHCLUSTER premium V1",(E5*$P$8)-B5+C5,IF(D5="Bez prodejů",-B5+C5,""))) -> 0 | G5: Celkem kusů | H5: =SUM(E4:E33)+SUM(E37:E67)+SUM(E71:E100)+SUM(E104:E134)+SUM(E138:E168)+SUM(E172:E201)+SUM(E205:E235)+SUM(E239:E268)+SUM(E272:E302) -> 0 | J5: Celkové náklady | L5: ='DASHCLUSTER classic V1'!M9 -> 368.55073 | N5: Celkové náklady | P5: ='DASHCLUSTER premium V1'!M9 -> 853.33692
A6: 3. dubna | D6: Bez prodejů | F6: =IF(D6="DASHCLUSTER classic V1",(E6*$L$8)-B6+C6,IF(D6="DASHCLUSTER premium V1",(E6*$P$8)-B6+C6,IF(D6="Bez prodejů",-B6+C6,""))) -> 0 | G6: Celkově čisté | H6: {=SUM((F4:F33)+SUM(F37:F67)+SUM(F71:F100)+SUM(F104:F134)+SUM(F138:F168)+SUM(F172:F201)+SUM(F205:F235)+SUM(F239:F268)+SUM(F272:F302))*(1-L4)} -> 0 | J6: Hrubý výdělek | L6: ='DASHCLUSTER classic V1'!M10 -> 995.08698 | N6: Hrubý výdělek | P6: ='DASHCLUSTER premium V1'!M10 -> 1280.0054
A7: 4. dubna | D7: Bez prodejů | F7: =IF(D7="DASHCLUSTER classic V1",(E7*$L$8)-B7+C7,IF(D7="DASHCLUSTER premium V1",(E7*$P$8)-B7+C7,IF(D7="Bez prodejů",-B7+C7,""))) -> 0 | G7: Celkově /2 | H7: =H6/2 -> 0 | J7: Výdělek bez nákladů | L7: ='DASHCLUSTER classic V1'!M11 -> 630.44927 | N7: Výdělek bez nákladů | P7: ='DASHCLUSTER premium V1'!M11 -> 445.66308
A8: 5. dubna | D8: Bez prodejů | F8: =IF(D8="DASHCLUSTER classic V1",(E8*$L$8)-B8+C8,IF(D8="DASHCLUSTER premium V1",(E8*$P$8)-B8+C8,IF(D8="Bez prodejů",-B8+C8,""))) -> 0 | G8: Investice /2 | H8: =0-SUM(J13:J33)/2 -> -504.225 | J8: Čistý výdělek | L8: ='DASHCLUSTER classic V1'!M12 -> 535.88188 | N8: Čistý výdělek | P8: ='DASHCLUSTER premium V1'!M12 -> 378.81362
A9: 6. dubna | D9: Bez prodejů | F9: =IF(D9="DASHCLUSTER classic V1",(E9*$L$8)-B9+C9,IF(D9="DASHCLUSTER premium V1",(E9*$P$8)-B9+C9,IF(D9="Bez prodejů",-B9+C9,""))) -> 0 | G9: Investice | H9: =0-SUM(J13:J33) -> -1008.45 | J9: Prodejní cena | L9: ='DASHCLUSTER classic V1'!M13 -> 999 | N9: Prodejní cena | P9: ='DASHCLUSTER premium V1'!M13 -> 1299
A10: 7. dubna | D10: Bez prodejů | F10: =IF(D10="DASHCLUSTER classic V1",(E10*$L$8)-B10+C10,IF(D10="DASHCLUSTER premium V1",(E10*$P$8)-B10+C10,IF(D10="Bez prodejů",-B10+C10,""))) -> 0
A11: 8. dubna | D11: Bez prodejů | F11: =IF(D11="DASHCLUSTER classic V1",(E11*$L$8)-B11+C11,IF(D11="DASHCLUSTER premium V1",(E11*$P$8)-B11+C11,IF(D11="Bez prodejů",-B11+C11,""))) -> 0 | H11: Seznam nákupů surovin | O11: Zaplaceno
A12: 9. dubna | D12: Bez prodejů | F12: =IF(D12="DASHCLUSTER classic V1",(E12*$L$8)-B12+C12,IF(D12="DASHCLUSTER premium V1",(E12*$P$8)-B12+C12,IF(D12="Bez prodejů",-B12+C12,""))) -> 0 | H12: Položka | J12: Cena | K12: Datum | L12: Faktury | O12: Anty | Q12: Bartonis
A13: 10. dubna | D13: Bez prodejů | F13: =IF(D13="DASHCLUSTER classic V1",(E13*$L$8)-B13+C13,IF(D13="DASHCLUSTER premium V1",(E13*$P$8)-B13+C13,IF(D13="Bez prodejů",-B13+C13,""))) -> 0 | H13: PCB 5ks | J13: 362.45 | K13: 46049 | L13: https://d.docs.live.net/5bfe2883faedf2c4/Desktop/dash%20cluster/ucetnictvi/faktury%20prichozi/27012026_JLCpcb.pdf | O13: 1008.45 | P13: 46049 | Q13: 500 | R13: 46076
A14: 11. dubna | D14: Bez prodejů | F14: =IF(D14="DASHCLUSTER classic V1",(E14*$L$8)-B14+C14,IF(D14="DASHCLUSTER premium V1",(E14*$P$8)-B14+C14,IF(D14="Bez prodejů",-B14+C14,""))) -> 0 | H14: Mikropájka a lišta | J14: 168 | K14: 46062 | L14: https://d.docs.live.net/5bfe2883faedf2c4/Desktop/dash%20cluster/ucetnictvi/faktury%20prichozi/09022026_LaskaKit.pdf | O14: Vyrovnáno
A15: 12. dubna | D15: Bez prodejů | F15: =IF(D15="DASHCLUSTER classic V1",(E15*$L$8)-B15+C15,IF(D15="DASHCLUSTER premium V1",(E15*$P$8)-B15+C15,IF(D15="Bez prodejů",-B15+C15,""))) -> 0 | H15: Elektrolytický k. | J15: 69.72 | K15: 46067 | L15: https://d.docs.live.net/5bfe2883faedf2c4/Desktop/dash%20cluster/ucetnictvi/faktury%20prichozi/25v1000ufC_aliexpress.png
A16: 13. dubna | D16: Bez prodejů | F16: =IF(D16="DASHCLUSTER classic V1",(E16*$L$8)-B16+C16,IF(D16="DASHCLUSTER premium V1",(E16*$P$8)-B16+C16,IF(D16="Bez prodejů",-B16+C16,""))) -> 0 | H16: Black Switche | J16: 173.78 | K16: 46067 | L16: https://d.docs.live.net/5bfe2883faedf2c4/Desktop/dash%20cluster/ucetnictvi/faktury%20prichozi/blackswitch_aliexpress.png | O16: Čeká
A17: 14. dubna | D17: Bez prodejů | F17: =IF(D17="DASHCLUSTER classic V1",(E17*$L$8)-B17+C17,IF(D17="DASHCLUSTER premium V1",(E17*$P$8)-B17+C17,IF(D17="Bez prodejů",-B17+C17,""))) -> 0 | H17: Keramický k. | J17: 38.64 | K17: 46067 | L17: https://d.docs.live.net/5bfe2883faedf2c4/Desktop/dash%20cluster/ucetnictvi/faktury%20prichozi/50v100nfC_aliexpress.png
A18: 15. dubna | D18: Bez prodejů | F18: =IF(D18="DASHCLUSTER classic V1",(E18*$L$8)-B18+C18,IF(D18="DASHCLUSTER premium V1",(E18*$P$8)-B18+C18,IF(D18="Bez prodejů",-B18+C18,""))) -> 0 | H18: WS2812B | J18: 116.33 | K18: 46067 | L18: https://d.docs.live.net/5bfe2883faedf2c4/Desktop/dash%20cluster/ucetnictvi/faktury%20prichozi/ws2812b5vDC_aliexpress.png | O18: Čeká
A19: 16. dubna | D19: Bez prodejů | F19: =IF(D19="DASHCLUSTER classic V1",(E19*$L$8)-B19+C19,IF(D19="DASHCLUSTER premium V1",(E19*$P$8)-B19+C19,IF(D19="Bez prodejů",-B19+C19,""))) -> 0 | H19: Rezistory | J19: 79.53 | K19: 46067 | L19: https://d.docs.live.net/5bfe2883faedf2c4/Desktop/dash%20cluster/ucetnictvi/faktury%20prichozi/30values330R0.25W_aliexpress.png
A20: 17. dubna | D20: Bez prodejů | F20: =IF(D20="DASHCLUSTER classic V1",(E20*$L$8)-B20+C20,IF(D20="DASHCLUSTER premium V1",(E20*$P$8)-B20+C20,IF(D20="Bez prodejů",-B20+C20,""))) -> 0 | O20: Čeká
A21: 18. dubna | D21: Bez prodejů | F21: =IF(D21="DASHCLUSTER classic V1",(E21*$L$8)-B21+C21,IF(D21="DASHCLUSTER premium V1",(E21*$P$8)-B21+C21,IF(D21="Bez prodejů",-B21+C21,""))) -> 0
A22: 19. dubna | D22: Bez prodejů | F22: =IF(D22="DASHCLUSTER classic V1",(E22*$L$8)-B22+C22,IF(D22="DASHCLUSTER premium V1",(E22*$P$8)-B22+C22,IF(D22="Bez prodejů",-B22+C22,""))) -> 0 | O22: Čeká
A23: 20. dubna | D23: Bez prodejů | F23: =IF(D23="DASHCLUSTER classic V1",(E23*$L$8)-B23+C23,IF(D23="DASHCLUSTER premium V1",(E23*$P$8)-B23+C23,IF(D23="Bez prodejů",-B23+C23,""))) -> 0
A24: 21. dubna | D24: Bez prodejů | F24: =IF(D24="DASHCLUSTER classic V1",(E24*$L$8)-B24+C24,IF(D24="DASHCLUSTER premium V1",(E24*$P$8)-B24+C24,IF(D24="Bez prodejů",-B24+C24,""))) -> 0 | O24: Čeká
A25: 22. dubna | D25: Bez prodejů | F25: =IF(D25="DASHCLUSTER classic V1",(E25*$L$8)-B25+C25,IF(D25="DASHCLUSTER premium V1",(E25*$P$8)-B25+C25,IF(D25="Bez prodejů",-B25+C25,""))) -> 0
A26: 23. dubna | D26: Bez prodejů | F26: =IF(D26="DASHCLUSTER classic V1",(E26*$L$8)-B26+C26,IF(D26="DASHCLUSTER premium V1",(E26*$P$8)-B26+C26,IF(D26="Bez prodejů",-B26+C26,""))) -> 0 | O26: Čeká
A27: 24. dubna | D27: Bez prodejů | F27: =IF(D27="DASHCLUSTER classic V1",(E27*$L$8)-B27+C27,IF(D27="DASHCLUSTER premium V1",(E27*$P$8)-B27+C27,IF(D27="Bez prodejů",-B27+C27,""))) -> 0
A28: 25. dubna | D28: Bez prodejů | F28: =IF(D28="DASHCLUSTER classic V1",(E28*$L$8)-B28+C28,IF(D28="DASHCLUSTER premium V1",(E28*$P$8)-B28+C28,IF(D28="Bez prodejů",-B28+C28,""))) -> 0 | O28: Čeká
A29: 26. dubna | D29: Bez prodejů | F29: =IF(D29="DASHCLUSTER classic V1",(E29*$L$8)-B29+C29,IF(D29="DASHCLUSTER premium V1",(E29*$P$8)-B29+C29,IF(D29="Bez prodejů",-B29+C29,""))) -> 0
A30: 27. dubna | D30: Bez prodejů | F30: =IF(D30="DASHCLUSTER classic V1",(E30*$L$8)-B30+C30,IF(D30="DASHCLUSTER premium V1",(E30*$P$8)-B30+C30,IF(D30="Bez prodejů",-B30+C30,""))) -> 0 | O30: Čeká
A31: 28. dubna | D31: Bez prodejů | F31: =IF(D31="DASHCLUSTER classic V1",(E31*$L$8)-B31+C31,IF(D31="DASHCLUSTER premium V1",(E31*$P$8)-B31+C31,IF(D31="Bez prodejů",-B31+C31,""))) -> 0
A32: 29. dubna | D32: Bez prodejů | F32: =IF(D32="DASHCLUSTER classic V1",(E32*$L$8)-B32+C32,IF(D32="DASHCLUSTER premium V1",(E32*$P$8)-B32+C32,IF(D32="Bez prodejů",-B32+C32,""))) -> 0 | O32: Čeká
A33: 30. dubna | D33: Bez prodejů | F33: =IF(D33="DASHCLUSTER classic V1",(E33*$L$8)-B33+C33,IF(D33="DASHCLUSTER premium V1",(E33*$P$8)-B33+C33,IF(D33="Bez prodejů",-B33+C33,""))) -> 0
O34: Čeká
A35: Květen
A36: Den | B36: Jiné výdaje (Kč) | C36: Jiné příjmy (Kč) | D36: Prodeje (vyber) | E36: Prodáno kusů | F36: Výsledek za den
A37: 1. května | D37: Bez prodejů | F37: =IF(D37="DASHCLUSTER classic V1",(E37*$L$8)-B37+C37,IF(D37="DASHCLUSTER premium V1",(E37*$P$8)-B37+C37,IF(D37="Bez prodejů",-B37+C37,""))) -> 0
A38: 2. května | D38: Bez prodejů | F38: =IF(D38="DASHCLUSTER classic V1",(E38*$L$8)-B38+C38,IF(D38="DASHCLUSTER premium V1",(E38*$P$8)-B38+C38,IF(D38="Bez prodejů",-B38+C38,""))) -> 0
A39: 3. května | D39: Bez prodejů | F39: =IF(D39="DASHCLUSTER classic V1",(E39*$L$8)-B39+C39,IF(D39="DASHCLUSTER premium V1",(E39*$P$8)-B39+C39,IF(D39="Bez prodejů",-B39+C39,""))) -> 0
A40: 4. května | D40: Bez prodejů | F40: =IF(D40="DASHCLUSTER classic V1",(E40*$L$8)-B40+C40,IF(D40="DASHCLUSTER premium V1",(E40*$P$8)-B40+C40,IF(D40="Bez prodejů",-B40+C40,""))) -> 0
...

Sheet Rok 2027
A1: Roční přehled | G1: Dnes je | H1: =TODAY() -> 46157 | J1: Přehled
A2: Duben | G2: Roční shrnutí | J2: DASHCLUSTER classic V1 | N2: DASHCLUSTER premium V1
A3: Den | B3: Jiné výdaje (Kč) | C3: Jiné příjmy (Kč) | D3: Prodeje (vyber) | E3: Prodáno kusů | F3: Výsledek za den | G3: Jiné výdaje | H3: =SUM(B4:B33)+SUM(B37:B67)+SUM(B71:B100)+SUM(B104:B134)+SUM(B138:B168)+SUM(B172:B201)+SUM(B205:B235)+SUM(B239:B268)+SUM(B272:B302) -> 0 | J3: Marže (v %) | L3: ='DASHCLUSTER classic V1'!L2 -> 1.7 | N3: Marže (v %) | P3: ='DASHCLUSTER premium V1'!L2 -> 0.5
A4: 1. dubna | D4: Bez prodejů | F4: =IF(D4="DASHCLUSTER classic V1",(E4*$L$8)-B4+C4,IF(D4="DASHCLUSTER premium V1",(E4*$P$8)-B4+C4,IF(D4="Bez prodejů",-B4+C4,""))) -> 0 | G4: Jiné příjmy | H4: =SUM(C4:C33)+SUM(C37:C67)+SUM(C71:C100)+SUM(C104:C134)+SUM(C138:C168)+SUM(C172:C201)+SUM(C205:C235)+SUM(C239:C268)+SUM(C272:C302) -> 0 | J4: Daň (v %) | L4: ='DASHCLUSTER classic V1'!L3 -> 0.15 | N4: Daň (v %) | P4: ='DASHCLUSTER premium V1'!L3 -> 0.15
A5: 2. dubna | D5: Bez prodejů | F5: =IF(D5="DASHCLUSTER classic V1",(E5*$L$8)-B5+C5,IF(D5="DASHCLUSTER premium V1",(E5*$P$8)-B5+C5,IF(D5="Bez prodejů",-B5+C5,""))) -> 0 | G5: Celkem kusů | H5: =SUM(E4:E33)+SUM(E37:E67)+SUM(E71:E100)+SUM(E104:E134)+SUM(E138:E168)+SUM(E172:E201)+SUM(E205:E235)+SUM(E239:E268)+SUM(E272:E302) -> 0 | J5: Celkové náklady | L5: ='DASHCLUSTER classic V1'!M9 -> 368.55073 | N5: Celkové náklady | P5: ='DASHCLUSTER premium V1'!M9 -> 853.33692
A6: 3. dubna | D6: Bez prodejů | F6: =IF(D6="DASHCLUSTER classic V1",(E6*$L$8)-B6+C6,IF(D6="DASHCLUSTER premium V1",(E6*$P$8)-B6+C6,IF(D6="Bez prodejů",-B6+C6,""))) -> 0 | G6: Celkově čisté | H6: {=SUM((F4:F33)+SUM(F37:F67)+SUM(F71:F100)+SUM(F104:F134)+SUM(F138:F168)+SUM(F172:F201)+SUM(F205:F235)+SUM(F239:F268)+SUM(F272:F302))*(1-L4)} -> 0 | J6: Hrubý výdělek | L6: ='DASHCLUSTER classic V1'!M10 -> 995.08698 | N6: Hrubý výdělek | P6: ='DASHCLUSTER premium V1'!M10 -> 1280.0054
A7: 4. dubna | D7: Bez prodejů | F7: =IF(D7="DASHCLUSTER classic V1",(E7*$L$8)-B7+C7,IF(D7="DASHCLUSTER premium V1",(E7*$P$8)-B7+C7,IF(D7="Bez prodejů",-B7+C7,""))) -> 0 | G7: Celkově /2 | H7: =H6/2 -> 0 | J7: Výdělek bez nákladů | L7: ='DASHCLUSTER classic V1'!M11 -> 630.44927 | N7: Výdělek bez nákladů | P7: ='DASHCLUSTER premium V1'!M11 -> 445.66308
A8: 5. dubna | D8: Bez prodejů | F8: =IF(D8="DASHCLUSTER classic V1",(E8*$L$8)-B8+C8,IF(D8="DASHCLUSTER premium V1",(E8*$P$8)-B8+C8,IF(D8="Bez prodejů",-B8+C8,""))) -> 0 | J8: Čistý výdělek | L8: ='DASHCLUSTER classic V1'!M12 -> 535.88188 | N8: Čistý výdělek | P8: ='DASHCLUSTER premium V1'!M12 -> 378.81362
A9: 6. dubna | D9: Bez prodejů | F9: =IF(D9="DASHCLUSTER classic V1",(E9*$L$8)-B9+C9,IF(D9="DASHCLUSTER premium V1",(E9*$P$8)-B9+C9,IF(D9="Bez prodejů",-B9+C9,""))) -> 0 | J9: Prodejní cena | L9: ='DASHCLUSTER classic V1'!M13 -> 999 | N9: Prodejní cena | P9: ='DASHCLUSTER premium V1'!M13 -> 1299
A10: 7. dubna | D10: Bez prodejů | F10: =IF(D10="DASHCLUSTER classic V1",(E10*$L$8)-B10+C10,IF(D10="DASHCLUSTER premium V1",(E10*$P$8)-B10+C10,IF(D10="Bez prodejů",-B10+C10,""))) -> 0
A11: 8. dubna | D11: Bez prodejů | F11: =IF(D11="DASHCLUSTER classic V1",(E11*$L$8)-B11+C11,IF(D11="DASHCLUSTER premium V1",(E11*$P$8)-B11+C11,IF(D11="Bez prodejů",-B11+C11,""))) -> 0
A12: 9. dubna | D12: Bez prodejů | F12: =IF(D12="DASHCLUSTER classic V1",(E12*$L$8)-B12+C12,IF(D12="DASHCLUSTER premium V1",(E12*$P$8)-B12+C12,IF(D12="Bez prodejů",-B12+C12,""))) -> 0
A13: 10. dubna | D13: Bez prodejů | F13: =IF(D13="DASHCLUSTER classic V1",(E13*$L$8)-B13+C13,IF(D13="DASHCLUSTER premium V1",(E13*$P$8)-B13+C13,IF(D13="Bez prodejů",-B13+C13,""))) -> 0
A14: 11. dubna | D14: Bez prodejů | F14: =IF(D14="DASHCLUSTER classic V1",(E14*$L$8)-B14+C14,IF(D14="DASHCLUSTER premium V1",(E14*$P$8)-B14+C14,IF(D14="Bez prodejů",-B14+C14,""))) -> 0
A15: 12. dubna | D15: Bez prodejů | F15: =IF(D15="DASHCLUSTER classic V1",(E15*$L$8)-B15+C15,IF(D15="DASHCLUSTER premium V1",(E15*$P$8)-B15+C15,IF(D15="Bez prodejů",-B15+C15,""))) -> 0
A16: 13. dubna | D16: Bez prodejů | F16: =IF(D16="DASHCLUSTER classic V1",(E16*$L$8)-B16+C16,IF(D16="DASHCLUSTER premium V1",(E16*$P$8)-B16+C16,IF(D16="Bez prodejů",-B16+C16,""))) -> 0
A17: 14. dubna | D17: Bez prodejů | F17: =IF(D17="DASHCLUSTER classic V1",(E17*$L$8)-B17+C17,IF(D17="DASHCLUSTER premium V1",(E17*$P$8)-B17+C17,IF(D17="Bez prodejů",-B17+C17,""))) -> 0
A18: 15. dubna | D18: Bez prodejů | F18: =IF(D18="DASHCLUSTER classic V1",(E18*$L$8)-B18+C18,IF(D18="DASHCLUSTER premium V1",(E18*$P$8)-B18+C18,IF(D18="Bez prodejů",-B18+C18,""))) -> 0
A19: 16. dubna | D19: Bez prodejů | F19: =IF(D19="DASHCLUSTER classic V1",(E19*$L$8)-B19+C19,IF(D19="DASHCLUSTER premium V1",(E19*$P$8)-B19+C19,IF(D19="Bez prodejů",-B19+C19,""))) -> 0
A20: 17. dubna | D20: Bez prodejů | F20: =IF(D20="DASHCLUSTER classic V1",(E20*$L$8)-B20+C20,IF(D20="DASHCLUSTER premium V1",(E20*$P$8)-B20+C20,IF(D20="Bez prodejů",-B20+C20,""))) -> 0
A21: 18. dubna | D21: Bez prodejů | F21: =IF(D21="DASHCLUSTER classic V1",(E21*$L$8)-B21+C21,IF(D21="DASHCLUSTER premium V1",(E21*$P$8)-B21+C21,IF(D21="Bez prodejů",-B21+C21,""))) -> 0
... A33: 30. dubna | D33: Bez prodejů | F33: =IF(D33="DASHCLUSTER classic V1",(E33*$L$8)-B33+C33,IF(D33="DASHCLUSTER premium V1",(E33*$P$8)-B33+C33,IF(D33="Bez prodejů",-B33+C33,""))) -> 0
A35: Květen
A36: Den | B36: Jiné výdaje (Kč) | C36: Jiné příjmy (Kč) | D36: Prodeje (vyber) | E36: Prodáno kusů | F36: Výsledek za den
A37: 1. května | D37: Bez prodejů | F37: =IF(D37="DASHCLUSTER classic V1",(E37*$L$8)-B37+C37,IF(D37="DASHCLUSTER premium V1",(E37*$P$8)-B37+C37,IF(D37="Bez prodejů",-B37+C37,""))) -> 0
A38: 2. května | D38: Bez prodejů | F38: =IF(D38="DASHCLUSTER classic V1",(E38*$L$8)-B38+C38,IF(D38="DASHCLUSTER premium V1",(E38*$P$8)-B38+C38,IF(D38="Bez prodejů",-B38+C38,""))) -> 0
A39: 3. května | D39: Bez prodejů | F39: =IF(D39="DASHCLUSTER classic V1",(E39*$L$8)-B39+C39,IF(D39="DASHCLUSTER premium V1",(E39*$P$8)-B39+C39,IF(D39="Bez prodejů",-B39+C39,""))) -> 0
A40: 4. května | D40: Bez prodejů | F40: =IF(D40="DASHCLUSTER classic V1",(E40*$L$8)-B40+C40,IF(D40="DASHCLUSTER premium V1",(E40*$P$8)-B40+C40,IF(D40="Bez prodejů",-B40+C40,""))) -> 0
A41: 5. května | D41: Bez prodejů | F41: =IF(D41="DASHCLUSTER classic V1",(E41*$L$8)-B41+C41,IF(D41="DASHCLUSTER premium V1",(E41*$P$8)-B41+C41,IF(D41="Bez prodejů",-B41+C41,""))) -> 0
A42: 6. května | D42: Bez prodejů | F42: =IF(D42="DASHCLUSTER classic V1",(E42*$L$8)-B42+C42,IF(D42="DASHCLUSTER premium V1",(E42*$P$8)-B42+C42,IF(D42="Bez prodejů",-B42+C42,""))) -> 0
A43: 7. května | D43: Bez prodejů | F43: =IF(D43="DASHCLUSTER classic V1",(E43*$L$8)-B43+C43,IF(D43="DASHCLUSTER premium V1",(E43*$P$8)-B43+C43,IF(D43="Bez prodejů",-B43+C43,""))) -> 0
A44: 8. května | D44: Bez prodejů | F44: =IF(D44="DASHCLUSTER classic V1",(E44*$L$8)-B44+C44,IF(D44="DASHCLUSTER premium V1",(E44*$P$8)-B44+C44,IF(D44="Bez prodejů",-B44+C44,""))) -> 0
A45: 9. května | D45: Bez prodejů | F45: =IF(D45="DASHCLUSTER classic V1",(E45*$L$8)-B45+C45,IF(D45="DASHCLUSTER premium V1",(E45*$P$8)-B45+C45,IF(D45="Bez prodejů",-B45+C45,""))) -> 0
A46: 10. května | D46: Bez prodejů | F46: =IF(D46="DASHCLUSTER classic V1",(E46*$L$8)-B46+C46,IF(D46="DASHCLUSTER premium V1",(E46*$P$8)-B46+C46,IF(D46="Bez prodejů",-B46+C46,""))) -> 0
A47: 11. května | D47: Bez prodejů | F47: =IF(D47="DASHCLUSTER classic V1",(E47*$L$8)-B47+C47,IF(D47="DASHCLUSTER premium V1",(E47*$P$8)-B47+C47,IF(D47="Bez prodejů",-B47+C47,""))) -> 0
A48: 12. května | D48: Bez prodejů | F48: =IF(D48="DASHCLUSTER classic V1",(E48*$L$8)-B48+C48,IF(D48="DASHCLUSTER premium V1",(E48*$P$8)-B48+C48,IF(D48="Bez prodejů",-B48+C48,""))) -> 0
... A67: 31. května | D67: Bez prodejů | F67: =IF(D67="DASHCLUSTER classic V1",(E67*$L$8)-B67+C67,IF(D67="DASHCLUSTER premium V1",(E67*$P$8)-B67+C67,IF(D67="Bez prodejů",-B67+C67,""))) -> 0
A69: Červen
A70: Den | B70: Jiné výdaje (Kč) | C70: Jiné příjmy (Kč) | D70: Prodeje (vyber) | E70: Prodáno kusů | F70: Výsledek za den
A71: 1. června | D71: Bez prodejů | F71: =IF(D71="DASHCLUSTER classic V1",(E71*$L$8)-B71+C71,IF(D71="DASHCLUSTER premium V1",(E71*$P$8)-B71+C71,IF(D71="Bez prodejů",-B71+C71,""))) -> 0
...
